[2021-05-05 22:30:31] Текст ошибки: Undefined variable: test |  Файл: C:\web\OpenServer\domains\fw.loc\public\test\Error\index.php|  Строка:59
         
==================================
[2021-05-05 22:31:44] Текст ошибки: Undefined variable: test |  Файл: C:\web\OpenServer\domains\fw.loc\public\test\Error\index.php|  Строка:59
         
==================================
[2021-05-05 22:35:01] Текст ошибки: Uncaught TypeError: Argument 1 passed to ErrorHandler::exeptionHandler() must be an instance of Exception, instance of Error given in C:\web\OpenServer\domains\fw.loc\public\test\Error\index.php:44
Stack trace:
#0 [internal function]: ErrorHandler->exeptionHandler(Object(Error))
#1 {main}
  thrown |  Файл: C:\web\OpenServer\domains\fw.loc\public\test\Error\index.php|  Строка:44
         
==================================
[2021-05-05 22:35:07] Текст ошибки: Uncaught TypeError: Argument 1 passed to ErrorHandler::exeptionHandler() must be an instance of Exception, instance of Error given in C:\web\OpenServer\domains\fw.loc\public\test\Error\index.php:44
Stack trace:
#0 [internal function]: ErrorHandler->exeptionHandler(Object(Error))
#1 {main}
  thrown |  Файл: C:\web\OpenServer\domains\fw.loc\public\test\Error\index.php|  Строка:44
         
==================================
[2021-05-05 22:35:22] Текст ошибки: Uncaught TypeError: Argument 1 passed to ErrorHandler::exeptionHandler() must be an instance of Exception, instance of Error given in C:\web\OpenServer\domains\fw.loc\public\test\Error\index.php:44
Stack trace:
#0 [internal function]: ErrorHandler->exeptionHandler(Object(Error))
#1 {main}
  thrown |  Файл: C:\web\OpenServer\domains\fw.loc\public\test\Error\index.php|  Строка:44
         
==================================
[2021-05-05 22:35:24] Текст ошибки: Uncaught TypeError: Argument 1 passed to ErrorHandler::exeptionHandler() must be an instance of Exception, instance of Error given in C:\web\OpenServer\domains\fw.loc\public\test\Error\index.php:44
Stack trace:
#0 [internal function]: ErrorHandler->exeptionHandler(Object(Error))
#1 {main}
  thrown |  Файл: C:\web\OpenServer\domains\fw.loc\public\test\Error\index.php|  Строка:44
         
==================================
[2021-05-05 22:35:24] Текст ошибки: Uncaught TypeError: Argument 1 passed to ErrorHandler::exeptionHandler() must be an instance of Exception, instance of Error given in C:\web\OpenServer\domains\fw.loc\public\test\Error\index.php:44
Stack trace:
#0 [internal function]: ErrorHandler->exeptionHandler(Object(Error))
#1 {main}
  thrown |  Файл: C:\web\OpenServer\domains\fw.loc\public\test\Error\index.php|  Строка:44
         
==================================
[2021-05-05 22:35:25] Текст ошибки: Uncaught TypeError: Argument 1 passed to ErrorHandler::exeptionHandler() must be an instance of Exception, instance of Error given in C:\web\OpenServer\domains\fw.loc\public\test\Error\index.php:44
Stack trace:
#0 [internal function]: ErrorHandler->exeptionHandler(Object(Error))
#1 {main}
  thrown |  Файл: C:\web\OpenServer\domains\fw.loc\public\test\Error\index.php|  Строка:44
         
==================================
[2021-05-05 22:35:25] Текст ошибки: Uncaught TypeError: Argument 1 passed to ErrorHandler::exeptionHandler() must be an instance of Exception, instance of Error given in C:\web\OpenServer\domains\fw.loc\public\test\Error\index.php:44
Stack trace:
#0 [internal function]: ErrorHandler->exeptionHandler(Object(Error))
#1 {main}
  thrown |  Файл: C:\web\OpenServer\domains\fw.loc\public\test\Error\index.php|  Строка:44
         
==================================
[2021-05-05 22:35:25] Текст ошибки: Uncaught TypeError: Argument 1 passed to ErrorHandler::exeptionHandler() must be an instance of Exception, instance of Error given in C:\web\OpenServer\domains\fw.loc\public\test\Error\index.php:44
Stack trace:
#0 [internal function]: ErrorHandler->exeptionHandler(Object(Error))
#1 {main}
  thrown |  Файл: C:\web\OpenServer\domains\fw.loc\public\test\Error\index.php|  Строка:44
         
==================================
[2021-05-05 22:35:25] Текст ошибки: Uncaught TypeError: Argument 1 passed to ErrorHandler::exeptionHandler() must be an instance of Exception, instance of Error given in C:\web\OpenServer\domains\fw.loc\public\test\Error\index.php:44
Stack trace:
#0 [internal function]: ErrorHandler->exeptionHandler(Object(Error))
#1 {main}
  thrown |  Файл: C:\web\OpenServer\domains\fw.loc\public\test\Error\index.php|  Строка:44
         
==================================
[2021-05-05 22:35:25] Текст ошибки: Uncaught TypeError: Argument 1 passed to ErrorHandler::exeptionHandler() must be an instance of Exception, instance of Error given in C:\web\OpenServer\domains\fw.loc\public\test\Error\index.php:44
Stack trace:
#0 [internal function]: ErrorHandler->exeptionHandler(Object(Error))
#1 {main}
  thrown |  Файл: C:\web\OpenServer\domains\fw.loc\public\test\Error\index.php|  Строка:44
         
==================================
[2021-05-05 22:35:26] Текст ошибки: Uncaught TypeError: Argument 1 passed to ErrorHandler::exeptionHandler() must be an instance of Exception, instance of Error given in C:\web\OpenServer\domains\fw.loc\public\test\Error\index.php:44
Stack trace:
#0 [internal function]: ErrorHandler->exeptionHandler(Object(Error))
#1 {main}
  thrown |  Файл: C:\web\OpenServer\domains\fw.loc\public\test\Error\index.php|  Строка:44
         
==================================
[2021-05-05 22:35:26] Текст ошибки: Uncaught TypeError: Argument 1 passed to ErrorHandler::exeptionHandler() must be an instance of Exception, instance of Error given in C:\web\OpenServer\domains\fw.loc\public\test\Error\index.php:44
Stack trace:
#0 [internal function]: ErrorHandler->exeptionHandler(Object(Error))
#1 {main}
  thrown |  Файл: C:\web\OpenServer\domains\fw.loc\public\test\Error\index.php|  Строка:44
         
==================================
[2021-05-05 22:35:27] Текст ошибки: Uncaught TypeError: Argument 1 passed to ErrorHandler::exeptionHandler() must be an instance of Exception, instance of Error given in C:\web\OpenServer\domains\fw.loc\public\test\Error\index.php:44
Stack trace:
#0 [internal function]: ErrorHandler->exeptionHandler(Object(Error))
#1 {main}
  thrown |  Файл: C:\web\OpenServer\domains\fw.loc\public\test\Error\index.php|  Строка:44
         
==================================
[2021-05-05 22:35:27] Текст ошибки: Uncaught TypeError: Argument 1 passed to ErrorHandler::exeptionHandler() must be an instance of Exception, instance of Error given in C:\web\OpenServer\domains\fw.loc\public\test\Error\index.php:44
Stack trace:
#0 [internal function]: ErrorHandler->exeptionHandler(Object(Error))
#1 {main}
  thrown |  Файл: C:\web\OpenServer\domains\fw.loc\public\test\Error\index.php|  Строка:44
         
==================================
[2021-05-05 22:35:27] Текст ошибки: Uncaught TypeError: Argument 1 passed to ErrorHandler::exeptionHandler() must be an instance of Exception, instance of Error given in C:\web\OpenServer\domains\fw.loc\public\test\Error\index.php:44
Stack trace:
#0 [internal function]: ErrorHandler->exeptionHandler(Object(Error))
#1 {main}
  thrown |  Файл: C:\web\OpenServer\domains\fw.loc\public\test\Error\index.php|  Строка:44
         
==================================
[2021-05-05 22:35:27] Текст ошибки: Uncaught TypeError: Argument 1 passed to ErrorHandler::exeptionHandler() must be an instance of Exception, instance of Error given in C:\web\OpenServer\domains\fw.loc\public\test\Error\index.php:44
Stack trace:
#0 [internal function]: ErrorHandler->exeptionHandler(Object(Error))
#1 {main}
  thrown |  Файл: C:\web\OpenServer\domains\fw.loc\public\test\Error\index.php|  Строка:44
         
==================================
[2021-05-05 22:35:28] Текст ошибки: Uncaught TypeError: Argument 1 passed to ErrorHandler::exeptionHandler() must be an instance of Exception, instance of Error given in C:\web\OpenServer\domains\fw.loc\public\test\Error\index.php:44
Stack trace:
#0 [internal function]: ErrorHandler->exeptionHandler(Object(Error))
#1 {main}
  thrown |  Файл: C:\web\OpenServer\domains\fw.loc\public\test\Error\index.php|  Строка:44
         
==================================
[2021-05-05 22:35:28] Текст ошибки: Uncaught TypeError: Argument 1 passed to ErrorHandler::exeptionHandler() must be an instance of Exception, instance of Error given in C:\web\OpenServer\domains\fw.loc\public\test\Error\index.php:44
Stack trace:
#0 [internal function]: ErrorHandler->exeptionHandler(Object(Error))
#1 {main}
  thrown |  Файл: C:\web\OpenServer\domains\fw.loc\public\test\Error\index.php|  Строка:44
         
==================================
[2021-05-05 22:35:28] Текст ошибки: Uncaught TypeError: Argument 1 passed to ErrorHandler::exeptionHandler() must be an instance of Exception, instance of Error given in C:\web\OpenServer\domains\fw.loc\public\test\Error\index.php:44
Stack trace:
#0 [internal function]: ErrorHandler->exeptionHandler(Object(Error))
#1 {main}
  thrown |  Файл: C:\web\OpenServer\domains\fw.loc\public\test\Error\index.php|  Строка:44
         
==================================
[2021-05-05 22:35:29] Текст ошибки: Uncaught TypeError: Argument 1 passed to ErrorHandler::exeptionHandler() must be an instance of Exception, instance of Error given in C:\web\OpenServer\domains\fw.loc\public\test\Error\index.php:44
Stack trace:
#0 [internal function]: ErrorHandler->exeptionHandler(Object(Error))
#1 {main}
  thrown |  Файл: C:\web\OpenServer\domains\fw.loc\public\test\Error\index.php|  Строка:44
         
==================================
[2021-05-05 22:35:29] Текст ошибки: Uncaught TypeError: Argument 1 passed to ErrorHandler::exeptionHandler() must be an instance of Exception, instance of Error given in C:\web\OpenServer\domains\fw.loc\public\test\Error\index.php:44
Stack trace:
#0 [internal function]: ErrorHandler->exeptionHandler(Object(Error))
#1 {main}
  thrown |  Файл: C:\web\OpenServer\domains\fw.loc\public\test\Error\index.php|  Строка:44
         
==================================
[2021-05-05 22:35:29] Текст ошибки: Uncaught TypeError: Argument 1 passed to ErrorHandler::exeptionHandler() must be an instance of Exception, instance of Error given in C:\web\OpenServer\domains\fw.loc\public\test\Error\index.php:44
Stack trace:
#0 [internal function]: ErrorHandler->exeptionHandler(Object(Error))
#1 {main}
  thrown |  Файл: C:\web\OpenServer\domains\fw.loc\public\test\Error\index.php|  Строка:44
         
==================================
[2021-05-05 22:35:29] Текст ошибки: Uncaught TypeError: Argument 1 passed to ErrorHandler::exeptionHandler() must be an instance of Exception, instance of Error given in C:\web\OpenServer\domains\fw.loc\public\test\Error\index.php:44
Stack trace:
#0 [internal function]: ErrorHandler->exeptionHandler(Object(Error))
#1 {main}
  thrown |  Файл: C:\web\OpenServer\domains\fw.loc\public\test\Error\index.php|  Строка:44
         
==================================
[2021-05-05 22:35:30] Текст ошибки: Uncaught TypeError: Argument 1 passed to ErrorHandler::exeptionHandler() must be an instance of Exception, instance of Error given in C:\web\OpenServer\domains\fw.loc\public\test\Error\index.php:44
Stack trace:
#0 [internal function]: ErrorHandler->exeptionHandler(Object(Error))
#1 {main}
  thrown |  Файл: C:\web\OpenServer\domains\fw.loc\public\test\Error\index.php|  Строка:44
         
==================================
[2021-05-05 22:35:30] Текст ошибки: Uncaught TypeError: Argument 1 passed to ErrorHandler::exeptionHandler() must be an instance of Exception, instance of Error given in C:\web\OpenServer\domains\fw.loc\public\test\Error\index.php:44
Stack trace:
#0 [internal function]: ErrorHandler->exeptionHandler(Object(Error))
#1 {main}
  thrown |  Файл: C:\web\OpenServer\domains\fw.loc\public\test\Error\index.php|  Строка:44
         
==================================
[2021-05-05 22:35:30] Текст ошибки: Uncaught TypeError: Argument 1 passed to ErrorHandler::exeptionHandler() must be an instance of Exception, instance of Error given in C:\web\OpenServer\domains\fw.loc\public\test\Error\index.php:44
Stack trace:
#0 [internal function]: ErrorHandler->exeptionHandler(Object(Error))
#1 {main}
  thrown |  Файл: C:\web\OpenServer\domains\fw.loc\public\test\Error\index.php|  Строка:44
         
==================================
[2021-05-05 22:35:30] Текст ошибки: Uncaught TypeError: Argument 1 passed to ErrorHandler::exeptionHandler() must be an instance of Exception, instance of Error given in C:\web\OpenServer\domains\fw.loc\public\test\Error\index.php:44
Stack trace:
#0 [internal function]: ErrorHandler->exeptionHandler(Object(Error))
#1 {main}
  thrown |  Файл: C:\web\OpenServer\domains\fw.loc\public\test\Error\index.php|  Строка:44
         
==================================
[2021-05-05 22:35:30] Текст ошибки: Uncaught TypeError: Argument 1 passed to ErrorHandler::exeptionHandler() must be an instance of Exception, instance of Error given in C:\web\OpenServer\domains\fw.loc\public\test\Error\index.php:44
Stack trace:
#0 [internal function]: ErrorHandler->exeptionHandler(Object(Error))
#1 {main}
  thrown |  Файл: C:\web\OpenServer\domains\fw.loc\public\test\Error\index.php|  Строка:44
         
==================================
[2021-05-05 22:35:31] Текст ошибки: Uncaught TypeError: Argument 1 passed to ErrorHandler::exeptionHandler() must be an instance of Exception, instance of Error given in C:\web\OpenServer\domains\fw.loc\public\test\Error\index.php:44
Stack trace:
#0 [internal function]: ErrorHandler->exeptionHandler(Object(Error))
#1 {main}
  thrown |  Файл: C:\web\OpenServer\domains\fw.loc\public\test\Error\index.php|  Строка:44
         
==================================
[2021-05-05 22:36:23] Текст ошибки: Call to undefined function test() |  Файл: C:\web\OpenServer\domains\fw.loc\public\test\Error\index.php|  Строка:64
         
==================================
[2021-05-05 22:36:50] Текст ошибки: Упс, исключение |  Файл: C:\web\OpenServer\domains\fw.loc\public\test\Error\index.php|  Строка:74
         
==================================
